Workbook

Sheet Serviços
A1: Tabela de Custos de Serviços de TI
A2: Software House / Manutenção de Computadores — dados de teste para importação
A4: ID | B4: Categoria | C4: Serviço | D4: Descrição | E4: Unidade de Cobrança | F4: Preço (R$) | G4: Tempo Estimado (h) | H4: Observações
A5: 1 | B5: Manutenção de Hardware | C5: Formatação e reinstalação do SO | D5: Backup, formatação e reinstalação do sistema operacional com drivers | E5: Por serviço | F5: 120 | G5: 2 | H5: Não inclui backup em nuvem
A6: 2 | B6: Manutenção de Hardware | C6: Limpeza interna (notebook) | D6: Limpeza de poeira, cooler e troca de pasta térmica | E6: Por serviço | F6: 90 | G6: 1
A7: 3 | B7: Manutenção de Hardware | C7: Limpeza interna (desktop) | D7: Limpeza de poeira, cooler e troca de pasta térmica | E7: Por serviço | F7: 80 | G7: 1
A8: 4 | B8: Manutenção de Hardware | C8: Troca de HD para SSD | D8: Clonagem de disco e instalação de SSD | E8: Por serviço | F8: 100 | G8: 1.5 | H8: Peça não inclusa
A9: 5 | B9: Manutenção de Hardware | C9: Upgrade de memória RAM | D9: Instalação e teste de novos módulos de memória | E9: Por serviço | F9: 60 | G9: 0.5 | H9: Peça não inclusa
A10: 6 | B10: Manutenção de Hardware | C10: Troca de tela de notebook | D10: Substituição de tela LCD/LED danificada | E10: Por serviço | F10: 150 | G10: 2 | H10: Peça não inclusa
A11: 7 | B11: Manutenção de Hardware | C11: Troca de teclado de notebook | D11: Substituição de teclado com defeito | E11: Por serviço | F11: 100 | G11: 1 | H11: Peça não inclusa
A12: 8 | B12: Manutenção de Hardware | C12: Diagnóstico de placa-mãe | D12: Identificação de falhas em componentes da placa-mãe | E12: Por serviço | F12: 80 | G12: 1
A13: 9 | B13: Manutenção de Hardware | C13: Troca de bateria de notebook | D13: Substituição de bateria com baixa autonomia | E13: Por serviço | F13: 70 | G13: 0.5 | H13: Peça não inclusa
A14: 10 | B14: Manutenção de Hardware | C14: Montagem de computador | D14: Montagem completa de PC gamer ou workstation | E14: Por serviço | F14: 200 | G14: 3 | H14: Peças não inclusas
A15: 11 | B15: Manutenção de Software | C15: Remoção de vírus e malware | D15: Varredura completa e remoção de ameaças | E15: Por serviço | F15: 100 | G15: 2
A16: 12 | B16: Manutenção de Software | C16: Instalação do pacote Office | D16: Instalação e ativação do Microsoft Office | E16: Por serviço | F16: 70 | G16: 1 | H16: Licença não inclusa
A17: 13 | B17: Manutenção de Software | C17: Instalação de antivírus corporativo | D17: Instalação e configuração de solução antivírus | E17: Por serviço | F17: 60 | G17: 0.5 | H17: Licença não inclusa
A18: 14 | B18: Manutenção de Software | C18: Atualização de drivers e sistema | D18: Atualização geral do Windows e drivers de hardware | E18: Por serviço | F18: 50 | G18: 1
A19: 15 | B19: Manutenção de Software | C19: Otimização de desempenho | D19: Limpeza de arquivos temporários e otimização de boot | E19: Por serviço | F19: 90 | G19: 1.5
A20: 16 | B20: Manutenção de Software | C20: Configuração de e-mail corporativo | D20: Configuração de conta no Outlook/cliente de e-mail | E20: Por serviço | F20: 60 | G20: 1
A21: 17 | B21: Manutenção de Software | C21: Migração de sistema operacional | D21: Migração entre versões de Windows ou para Linux | E21: Por serviço | F21: 150 | G21: 3
A22: 18 | B22: Manutenção de Software | C22: Ativação e licenciamento de software | D22: Regularização de licenças de sistema e aplicativos | E22: Por serviço | F22: 50 | G22: 0.5
A23: 19 | B23: Redes e Infraestrutura | C23: Instalação de Wi-Fi residencial | D23: Configuração de roteador e otimização de sinal | E23: Por serviço | F23: 150 | G23: 2
A24: 20 | B24: Redes e Infraestrutura | C24: Instalação de Wi-Fi empresarial | D24: Projeto e instalação de rede sem fio corporativa | E24: Por serviço | F24: 400 | G24: 5
A25: 21 | B25: Redes e Infraestrutura | C25: Cabeamento estruturado | D25: Passagem e certificação de ponto de rede | E25: Por ponto | F25: 80 | G25: 1 | H25: Valor por ponto instalado
A26: 22 | B26: Redes e Infraestrutura | C26: Configuração de roteador/switch | D26: Configuração de equipamentos de rede | E26: Por serviço | F26: 100 | G26: 1.5
A27: 23 | B27: Redes e Infraestrutura | C27: Instalação de servidor local | D27: Instalação e configuração de servidor de arquivos | E27: Por serviço | F27: 600 | G27: 8
A28: 24 | B28: Redes e Infraestrutura | C28: Configuração de VPN | D28: Configuração de acesso remoto seguro | E28: Por serviço | F28: 200 | G28: 2
A29: 25 | B29: Redes e Infraestrutura | C29: Monitoramento de rede | D29: Monitoramento contínuo de disponibilidade da rede | E29: Mensal | F29: 300 | H29: Cobrança recorrente
A30: 26 | B30: Redes e Infraestrutura | C30: Instalação de câmeras (CFTV) | D30: Instalação e configuração de câmera de segurança | E30: Por ponto | F30: 180 | G30: 2 | H30: Câmera não inclusa
A31: 27 | B31: Segurança da Informação | C31: Auditoria de segurança básica | D31: Avaliação de vulnerabilidades e boas práticas | E31: Por serviço | F31: 500 | G31: 6
A32: 28 | B32: Segurança da Informação | C32: Implementação de firewall | D32: Instalação e configuração de firewall de rede | E32: Por serviço | F32: 350 | G32: 4
A33: 29 | B33: Segurança da Informação | C33: Política de backup e segurança | D33: Consultoria para definição de políticas internas | E33: Por serviço | F33: 400 | G33: 4
A34: 30 | B34: Segurança da Informação | C34: Teste de vulnerabilidade (pentest básico) | D34: Análise de segurança em sistemas e rede | E34: Por serviço | F34: 800 | G34: 10
A35: 31 | B35: Segurança da Informação | C35: Configuração de autenticação em 2 fatores | D35: Implementação de 2FA em contas e sistemas | E35: Por serviço | F35: 80 | G35: 1
A36: 32 | B36: Desenvolvimento | C36: Site institucional | D36: Desenvolvimento de site institucional responsivo | E36: Por projeto | F36: 2500 | G36: 40 | H36: Valor pode variar conforme escopo
A37: 33 | B37: Desenvolvimento | C37: E-commerce | D37: Loja virtual completa com integração de pagamento | E37: Por projeto | F37: 6000 | G37: 80 | H37: Valor pode variar conforme escopo
A38: 34 | B38: Desenvolvimento | C38: Sistema web sob medida | D38: Desenvolvimento de sistema web personalizado | E38: Por hora | F38: 120 | H38: Cobrança por hora técnica
A39: 35 | B39: Desenvolvimento | C39: Manutenção mensal de sistema/site | D39: Atualizações, correções e pequenas melhorias | E39: Mensal | F39: 300 | H39: Cobrança recorrente
A40: 36 | B40: Desenvolvimento | C40: Aplicativo mobile básico | D40: Desenvolvimento de app Android/iOS (MVP) | E40: Por projeto | F40: 8000 | G40: 120 | H40: Valor pode variar conforme escopo
A41: 37 | B41: Desenvolvimento | C41: Landing page | D41: Criação de página de captura otimizada | E41: Por projeto | F41: 800 | G41: 10
...

Sheet Resumo por Categoria
A1: Resumo por Categoria
A3: Categoria | B3: Qtde. de Serviços | C3: Preço Médio (R$) | D3: Preço Mínimo (R$) | E3: Preço Máximo (R$)
A4: Manutenção de Hardware | B4: =COUNTIF(Serviços!$B$5:$B$60,A4) -> 10 | C4: =AVERAGEIF(Serviços!$B$5:$B$60,A4,Serviços!$F$5:$F$60) -> 105 | D4: =_xlfn.MINIFS(Serviços!$F$5:$F$60,Serviços!$B$5:$B$60,A4) -> 60 | E4: =_xlfn.MAXIFS(Serviços!$F$5:$F$60,Serviços!$B$5:$B$60,A4) -> 200
A5: Manutenção de Software | B5: =COUNTIF(Serviços!$B$5:$B$60,A5) -> 8 | C5: =AVERAGEIF(Serviços!$B$5:$B$60,A5,Serviços!$F$5:$F$60) -> 78.75 | D5: =_xlfn.MINIFS(Serviços!$F$5:$F$60,Serviços!$B$5:$B$60,A5) -> 50 | E5: =_xlfn.MAXIFS(Serviços!$F$5:$F$60,Serviços!$B$5:$B$60,A5) -> 150
A6: Redes e Infraestrutura | B6: =COUNTIF(Serviços!$B$5:$B$60,A6) -> 8 | C6: =AVERAGEIF(Serviços!$B$5:$B$60,A6,Serviços!$F$5:$F$60) -> 251.25 | D6: =_xlfn.MINIFS(Serviços!$F$5:$F$60,Serviços!$B$5:$B$60,A6) -> 80 | E6: =_xlfn.MAXIFS(Serviços!$F$5:$F$60,Serviços!$B$5:$B$60,A6) -> 600
A7: Segurança da Informação | B7: =COUNTIF(Serviços!$B$5:$B$60,A7) -> 5 | C7: =AVERAGEIF(Serviços!$B$5:$B$60,A7,Serviços!$F$5:$F$60) -> 426 | D7: =_xlfn.MINIFS(Serviços!$F$5:$F$60,Serviços!$B$5:$B$60,A7) -> 80 | E7: =_xlfn.MAXIFS(Serviços!$F$5:$F$60,Serviços!$B$5:$B$60,A7) -> 800
A8: Desenvolvimento | B8: =COUNTIF(Serviços!$B$5:$B$60,A8) -> 7 | C8: =AVERAGEIF(Serviços!$B$5:$B$60,A8,Serviços!$F$5:$F$60) -> 2602.8571 | D8: =_xlfn.MINIFS(Serviços!$F$5:$F$60,Serviços!$B$5:$B$60,A8) -> 120 | E8: =_xlfn.MAXIFS(Serviços!$F$5:$F$60,Serviços!$B$5:$B$60,A8) -> 8000
A9: Suporte Técnico | B9: =COUNTIF(Serviços!$B$5:$B$60,A9) -> 5 | C9: =AVERAGEIF(Serviços!$B$5:$B$60,A9,Serviços!$F$5:$F$60) -> 324 | D9: =_xlfn.MINIFS(Serviços!$F$5:$F$60,Serviços!$B$5:$B$60,A9) -> 70 | E9: =_xlfn.MAXIFS(Serviços!$F$5:$F$60,Serviços!$B$5:$B$60,A9) -> 800
A10: Backup e Recuperação | B10: =COUNTIF(Serviços!$B$5:$B$60,A10) -> 4 | C10: =AVERAGEIF(Serviços!$B$5:$B$60,A10,Serviços!$F$5:$F$60) -> 187.5 | D10: =_xlfn.MINIFS(Serviços!$F$5:$F$60,Serviços!$B$5:$B$60,A10) -> 120 | E10: =_xlfn.MAXIFS(Serviços!$F$5:$F$60,Serviços!$B$5:$B$60,A10) -> 300
A11: Consultoria em TI | B11: =COUNTIF(Serviços!$B$5:$B$60,A11) -> 3 | C11: =AVERAGEIF(Serviços!$B$5:$B$60,A11,Serviços!$F$5:$F$60) -> 593.33333 | D11: =_xlfn.MINIFS(Serviços!$F$5:$F$60,Serviços!$B$5:$B$60,A11) -> 180 | E11: =_xlfn.MAXIFS(Serviços!$F$5:$F$60,Serviços!$B$5:$B$60,A11) -> 1200
A12: Cloud / Nuvem | B12: =COUNTIF(Serviços!$B$5:$B$60,A12) -> 3 | C12: =AVERAGEIF(Serviços!$B$5:$B$60,A12,Serviços!$F$5:$F$60) -> 550 | D12: =_xlfn.MINIFS(Serviços!$F$5:$F$60,Serviços!$B$5:$B$60,A12) -> 250 | E12: =_xlfn.MAXIFS(Serviços!$F$5:$F$60,Serviços!$B$5:$B$60,A12) -> 900
A13: Impressoras e Periféricos | B13: =COUNTIF(Serviços!$B$5:$B$60,A13) -> 3 | C13: =AVERAGEIF(Serviços!$B$5:$B$60,A13,Serviços!$F$5:$F$60) -> 66.666667 | D13: =_xlfn.MINIFS(Serviços!$F$5:$F$60,Serviços!$B$5:$B$60,A13) -> 40 | E13: =_xlfn.MAXIFS(Serviços!$F$5:$F$60,Serviços!$B$5:$B$60,A13) -> 90
A15: TOTAL GERAL | B15: =SUM(B4:B13) -> 56 | C15: =AVERAGE(Serviços!$F$5:$F$60) -> 536.42857
